
<?xml version="1.0" encoding="utf-8"?>
<mujoco>
    <asset>
        <material name="machine_metal" rgba="0.7 0.7 0.7 1"/>
    </asset>
    
    <worldbody>
        <body>
            <body name="machine_main">
                <geom type="box" size="0.1 0.15 0.2" material="machine_metal"/>
            </body>
            <body name="lid" pos="0 0.15 0.2">
                <joint type="hinge" name="lid_joint" axis="1 0 0" limited="true" range="0 1.57"/>
                <geom type="box" size="0.1 0.075 0.01" material="machine_metal"/>
            </body>
            <body name="holder" pos="0 0 0.1">
                <joint type="slide" name="holder_joint" axis="0 1 0" limited="true" range="-0.2 0"/>
                <geom type="box" size="0.05 0.075 0.02" material="machine_metal"/>
            </body>
        </body>
    </worldbody>
</mujoco>
